<?xml version="1.0" ?>
<robot xmlns:xacro="http://ros.org/wiki/xacro">
  <xacro:macro name="motoman_ma2010" params="prefix">

    <!-- link list -->
    <link name="${prefix}base_link">
      <visual>
        <geometry>
          <mesh filename="package://motoman_ma2010_support/meshes/ma2010/visual/base_link.stl"/>
        </geometry>
        <material name="yaskawa_blue"/>
      </visual>
      <collision>
        <geometry>
          <mesh filename="package://motoman_ma2010_support/meshes/ma2010/collision/base_link.stl"/>
        </geometry>
      </collision>
    </link>
    <link name="${prefix}link_1_s">
      <visual>
        <geometry>
          <mesh filename="package://motoman_ma2010_support/meshes/ma2010/visual/link_1_s.stl"/>
        </geometry>
        <material name="yaskawa_blue"/>
      </visual>
      <collision>
        <geometry>
          <mesh filename="package://motoman_ma2010_support/meshes/ma2010/collision/link_1_s.stl"/>
        </geometry>
      </collision>
    </link>
    <link name="${prefix}link_2_l">
      <visual>
        <geometry>
          <mesh filename="package://motoman_ma2010_support/meshes/ma2010/visual/link_2_l.stl"/>
        </geometry>
        <material name="yaskawa_blue"/>
      </visual>
      <collision>
        <geometry>
          <mesh filename="package://motoman_ma2010_support/meshes/ma2010/collision/link_2_l.stl"/>
        </geometry>
      </collision>
    </link>
    <link name="${prefix}link_3_u">
      <visual>
        <geometry>
          <mesh filename="package://motoman_ma2010_support/meshes/ma2010/visual/link_3_u.stl"/>
        </geometry>
        <material name="yaskawa_blue"/>
      </visual>
      <collision>
        <geometry>
          <mesh filename="package://motoman_ma2010_support/meshes/ma2010/collision/link_3_u.stl"/>
        </geometry>
      </collision>
    </link>
    <link name="${prefix}link_4_r">
      <visual>
        <geometry>
          <mesh filename="package://motoman_ma2010_support/meshes/ma2010/visual/link_4_r.stl"/>
        </geometry>
        <material name="yaskawa_blue"/>
      </visual>
      <collision>
        <geometry>
          <mesh filename="package://motoman_ma2010_support/meshes/ma2010/collision/link_4_r.stl"/>
        </geometry>
      </collision>
    </link>
    <link name="${prefix}link_5_b">
      <visual>
        <geometry>
          <mesh filename="package://motoman_ma2010_support/meshes/ma2010/visual/link_5_b.stl"/>
        </geometry>
        <material name="yaskawa_blue"/>
      </visual>
      <collision>
        <geometry>
          <mesh filename="package://motoman_ma2010_support/meshes/ma2010/collision/link_5_b.stl"/>
        </geometry>
      </collision>
    </link>
    <link name="${prefix}link_6_t">
      <visual>
        <geometry>
          <mesh filename="package://motoman_ma2010_support/meshes/ma2010/visual/link_6_t.stl"/>
        </geometry>
        <material name="yaskawa_blue"/>
      </visual>
      <collision>
        <geometry>
          <mesh filename="package://motoman_ma2010_support/meshes/ma2010/collision/link_6_t.stl"/>
        </geometry>
      </collision>
    </link>
    <!-- end of link list -->

    <!-- joint list -->
    <joint name="${prefix}joint_1_s" type="revolute">
      <parent link="${prefix}base_link"/>
      <child link="${prefix}link_1_s"/>
      <origin xyz="0 0 0.505" rpy="0 0 0" />
      <axis xyz="0 0 1" />
      <limit lower="-3.1416" upper="3.1416" effort="3087" velocity="3.4383"/>
    </joint>
    <joint name="${prefix}joint_2_l" type="revolute">
      <parent link="${prefix}link_1_s"/>
      <child link="${prefix}link_2_l"/>
      <origin xyz="0.150 0 0" rpy="0 0 0" />
      <axis xyz="0 1 0" />
      <limit lower="-1.8326" upper="2.7052" effort="2744" velocity="3.3161"/>
    </joint>
    <joint name="${prefix}joint_3_u" type="revolute">
      <parent link="${prefix}link_2_l"/>
      <child link="${prefix}link_3_u"/>
      <origin xyz="0 0 0.760" rpy="0 0 0" />
      <axis xyz="0 -1 0" />
      <limit lower="-1.5009" upper="2.7925" effort="874.65" velocity="3.6652"/>
    </joint>
    <joint name="${prefix}joint_4_r" type="revolute">
      <parent link="${prefix}link_3_u"/>
      <child link="${prefix}link_4_r"/>
      <origin xyz="0 0 0.200" rpy="0 0 0" />
      <axis xyz="-1 0 0" />
      <limit lower="-2.6180" upper="2.6180" effort="78.4" velocity="7.1558"/>
    </joint>
    <joint name="${prefix}joint_5_b" type="revolute">
      <parent link="${prefix}link_4_r"/>
      <child link="${prefix}link_5_b"/>
      <origin xyz="1.082 0 0" rpy="0 0 0" />
      <axis xyz="0 -1 0" />
      <limit lower="-2.3562" upper="1.5708" effort="59.58" velocity="7.1558"/>
    </joint>
    <joint name="${prefix}joint_6_t" type="revolute">
      <parent link="${prefix}link_5_b"/>
      <child link="${prefix}link_6_t"/>
      <origin xyz="0 0 0" rpy="0 0 0" />
      <axis xyz="-1 0 0" />
      <limit lower="-3.6652" upper="3.6652" effort="29.6" velocity="10.6465"/>
    </joint>
    <!-- end of joint list -->

    <!-- ROS base_link to Robot Manufacturer World Coordinates transform -->
    <link name="${prefix}base" />
    <joint name="${prefix}base_link-base" type="fixed">
      <origin xyz="0 0 0.505" rpy="0 0 0"/>
      <parent link="${prefix}base_link"/>
      <child link="${prefix}base"/>
    </joint>

    <!-- ROS-Industrial 'tool0' frame: all-zeros tool frame -->
    <link name="${prefix}tool0"/>
    <joint name="${prefix}joint_6_t-tool0" type="fixed">
      <origin xyz="0.100 0 0" rpy="0 0 0"/>
      <parent link="${prefix}link_6_t"/>
      <child link="${prefix}tool0"/>
    </joint>
  </xacro:macro>
</robot>
