<?xml version="1.0" ?>
<!-- =================================================================================== -->
<!-- |    This document was autogenerated by xacro from mh6.xacro                      | -->
<!-- |    EDITING THIS FILE BY HAND IS NOT RECOMMENDED                                 | -->
<!-- =================================================================================== -->
<robot name="motoman_mh6" xmlns:xacro="http://ros.org/wiki/xacro">
  <!-- link list -->
  <link name="base_link">
    <visual>
      <geometry>
        <mesh filename="package://motoman_mh6_support/meshes/mh6/visual/MH6_BASE_AXIS.stl"/>
      </geometry>
      <material name="blue">
        <color rgba="0 0 1 1"/>
      </material>
    </visual>
    <collision>
      <geometry>
        <mesh filename="package://motoman_mh6_support/meshes/mh6/collision/MH6_BASE_AXIS.stl"/>
      </geometry>
      <material name="yellow">
        <color rgba="0 1 1 1"/>
      </material>
    </collision>
  </link>
  <link name="link_s">
    <visual>
      <geometry>
        <mesh filename="package://motoman_mh6_support/meshes/mh6/visual/MH6_S_AXIS.stl"/>
      </geometry>
      <material name="silver">
        <color rgba="0.8 0.8 0.8 1"/>
      </material>
    </visual>
    <collision>
      <geometry>
        <mesh filename="package://motoman_mh6_support/meshes/mh6/collision/MH6_S_AXIS.stl"/>
      </geometry>
      <material name="yellow"/>
    </collision>
  </link>
  <link name="link_l">
    <visual>
      <geometry>
        <mesh filename="package://motoman_mh6_support/meshes/mh6/visual/MH6_L_AXIS.stl"/>
      </geometry>
      <material name="blue"/>
    </visual>
    <collision>
      <geometry>
        <mesh filename="package://motoman_mh6_support/meshes/mh6/collision/MH6_L_AXIS.stl"/>
      </geometry>
      <material name="yellow"/>
    </collision>
  </link>
  <link name="link_u">
    <visual>
      <geometry>
        <mesh filename="package://motoman_mh6_support/meshes/mh6/visual/MH6_U_AXIS.stl"/>
      </geometry>
      <material name="silver"/>
    </visual>
    <collision>
      <geometry>
        <mesh filename="package://motoman_mh6_support/meshes/mh6/collision/MH6_U_AXIS.stl"/>
      </geometry>
      <material name="yellow"/>
    </collision>
  </link>
  <link name="link_r">
    <visual>
      <geometry>
        <mesh filename="package://motoman_mh6_support/meshes/mh6/visual/MH6_R_AXIS.stl"/>
      </geometry>
      <material name="blue"/>
    </visual>
    <collision>
      <geometry>
        <mesh filename="package://motoman_mh6_support/meshes/mh6/collision/MH6_R_AXIS.stl"/>
      </geometry>
      <material name="yellow"/>
    </collision>
  </link>
  <link name="link_b">
    <visual>
      <geometry>
        <mesh filename="package://motoman_mh6_support/meshes/mh6/visual/MH6_B_AXIS.stl"/>
      </geometry>
      <material name="silver"/>
    </visual>
    <collision>
      <geometry>
        <mesh filename="package://motoman_mh6_support/meshes/mh6/collision/MH6_B_AXIS.stl"/>
      </geometry>
      <material name="yellow"/>
    </collision>
  </link>
  <link name="link_t">
    <visual>
      <geometry>
        <mesh filename="package://motoman_mh6_support/meshes/mh6/visual/MH6_T_AXIS.stl"/>
      </geometry>
      <material name="blue"/>
    </visual>
    <collision>
      <geometry>
        <mesh filename="package://motoman_mh6_support/meshes/mh6/collision/MH6_T_AXIS.stl"/>
      </geometry>
      <material name="yellow"/>
    </collision>
  </link>
  <!-- end of link list -->
  <!-- joint list -->
  <joint name="joint_s" type="revolute">
    <parent link="base_link"/>
    <child link="link_s"/>
    <origin xyz="0 0 0"/>
    <axis xyz="0 0 1"/>
    <limit effort="100" lower="-2.96705972839" upper="2.96705972839" velocity="3.83972435439"/>
  </joint>
  <joint name="joint_l" type="revolute">
    <parent link="link_s"/>
    <child link="link_l"/>
    <origin xyz="0.152 0 0.450"/>
    <axis xyz="0 1 0"/>
    <limit effort="100" lower="-1.57079632679" upper="2.70526034059" velocity="3.49065850399"/>
  </joint>
  <joint name="joint_u" type="revolute">
    <parent link="link_l"/>
    <child link="link_u"/>
    <origin xyz="0 0 0.614"/>
    <axis xyz="0 -1 0"/>
    <!-- These limits are from the datasheet, but they always cause self collisions. -->
    <limit effort="100" lower="-3.05432619099" upper="4.36332312999" velocity="3.83972435439"/>
  </joint>
  <joint name="joint_r" type="revolute">
    <parent link="link_u"/>
    <child link="link_r"/>
    <origin xyz="0.197 0 0.155"/>
    <axis xyz="-1 0 0"/>
    <limit effort="100" lower="-3.14159265359" upper="3.14159265359" velocity="7.15584993318"/>
  </joint>
  <joint name="joint_b" type="revolute">
    <parent link="link_r"/>
    <child link="link_b"/>
    <origin xyz="0.443 0 0"/>
    <axis xyz="0 -1 0"/>
    <limit effort="100" lower="-0.785398163397" upper="3.92699081699" velocity="7.15584993318"/>
  </joint>
  <joint name="joint_t" type="revolute">
    <parent link="link_b"/>
    <child link="link_t"/>
    <origin xyz="0 0 -0.095"/>
    <axis xyz="0 0 1"/>
    <limit effort="100" lower="-6.28318530718" upper="6.28318530718" velocity="10.6465084372"/>
  </joint>
  <!-- end of joint list -->
</robot>
