<?xml version="1.0" ?>
<robot xmlns:xacro="http://ros.org/wiki/xacro">
<xacro:macro name="motoman_gp180" params="prefix">

    <xacro:include filename="$(find motoman_resources)/urdf/common_materials.xacro"/>

    <!-- link list -->
    <link name="${prefix}base_link">
        <visual>
            <geometry>
                <mesh filename="package://motoman_gp180_support/meshes/gp180_120/visual/base_link.stl"/>
            </geometry>
            <xacro:material_yaskawa_blue/>
        </visual>
        <collision>
            <geometry>
                <mesh filename="package://motoman_gp180_support/meshes/gp180_120/collision/base_link.stl"/>
            </geometry>
        </collision>
    </link>
    <link name="${prefix}link_1_s">
        <visual>
            <geometry>
                <mesh filename="package://motoman_gp180_support/meshes/gp180_120/visual/link_1_s.stl"/>
            </geometry>
            <xacro:material_yaskawa_blue/>
        </visual>
        <collision>
            <geometry>
                <mesh filename="package://motoman_gp180_support/meshes/gp180_120/collision/link_1_s.stl"/>
            </geometry>
        </collision>
    </link>
    <link name="${prefix}link_2_l">
        <visual>
            <origin rpy="${radians(90)} ${radians(0)} ${radians(90)}" />
            <geometry>
                <mesh filename="package://motoman_gp180_support/meshes/gp180_120/visual/link_2_l.stl"/>
            </geometry>
            <xacro:material_yaskawa_blue/>
        </visual>
        <collision>
            <origin rpy="${radians(90)} ${radians(0)} ${radians(90)}" />
            <geometry>
                <mesh filename="package://motoman_gp180_support/meshes/gp180_120/collision/link_2_l.stl"/>
            </geometry>
        </collision>
    </link>
    <link name="${prefix}link_3_u">
        <visual>
            <origin rpy="${radians(-90)} ${radians(0)} ${radians(-90)}" />
            <geometry>
                <mesh filename="package://motoman_gp180_support/meshes/gp180/visual/link_3_u.stl"/>
            </geometry>
            <xacro:material_yaskawa_blue/>
        </visual>
        <collision>
            <origin rpy="${radians(-90)} ${radians(0)} ${radians(-90)}" />
            <geometry>
                <mesh filename="package://motoman_gp180_support/meshes/gp180/collision/link_3_u.stl"/>
            </geometry>
        </collision>
    </link>
    <link name="${prefix}link_4_r">
        <visual>
            <origin rpy="${radians(0)} ${radians(90)} ${radians(0)}" xyz="0 0 1.225"/>
            <geometry>
                <mesh filename="package://motoman_gp180_support/meshes/gp180/visual/link_4_r.stl"/>
            </geometry>
            <xacro:material_yaskawa_blue/>
        </visual>
        <collision>
            <origin rpy="${radians(0)} ${radians(90)} ${radians(0)}" xyz="0 0 1.225"/>
            <geometry>
                <mesh filename="package://motoman_gp180_support/meshes/gp180/collision/link_4_r.stl"/>
            </geometry>
        </collision>
    </link>
    <link name="${prefix}link_5_b">
        <visual>
            <origin rpy="${radians(-90)} ${radians(0)} ${radians(-90)}" />
            <geometry>
                <mesh filename="package://motoman_gp180_support/meshes/gp180_120/visual/link_5_b.stl"/>
            </geometry>
            <xacro:material_yaskawa_blue/>
        </visual>
        <collision>
            <origin rpy="${radians(-90)} ${radians(0)} ${radians(-90)}" />
            <geometry>
                <mesh filename="package://motoman_gp180_support/meshes/gp180_120/collision/link_5_b.stl"/>
            </geometry>
        </collision>
    </link>
    <link name="${prefix}link_6_t">
        <visual>
            <origin rpy="${radians(0)} ${radians(90)} ${radians(0)}" />
            <geometry>
                <mesh filename="package://motoman_gp180_support/meshes/gp180_120/visual/link_6_t.stl"/>
            </geometry>
            <xacro:material_yaskawa_blue/>
        </visual>
        <collision>
            <origin rpy="${radians(0)} ${radians(90)} ${radians(0)}" />
            <geometry>
                <mesh filename="package://motoman_gp180_support/meshes/gp180_120/collision/link_6_t.stl"/>
            </geometry>
        </collision>
    </link>
    <!-- end of link list -->

    <!-- joint list -->
    <joint name="${prefix}joint_1_s" type="revolute">
        <parent link="${prefix}base_link"/>
        <child link="${prefix}link_1_s"/>
        <origin xyz="0 0 0.650" rpy="0 0 0" />
        <axis xyz="0 0 1" />
        <limit lower="${radians(-180)}" upper="${radians(180)}" effort="8237.59" velocity="${radians(125)}"/>
    </joint>
    <joint name="${prefix}joint_2_l" type="revolute">
        <parent link="${prefix}link_1_s"/>
        <child link="${prefix}link_2_l"/>
        <origin xyz="0.325 0 0" rpy="0 ${radians(-90)} ${radians(-90)}" />
        <axis xyz="0 0 1" />
        <limit lower="${radians(-60)}" upper="${radians(76)}" effort="10419.57" velocity="${radians(115)}"/>
    </joint>
    <joint name="${prefix}joint_3_u" type="revolute">
        <parent link="${prefix}link_2_l"/>
        <child link="${prefix}link_3_u"/>
        <origin xyz="1.150 0 0" rpy="${radians(180)} 0 0" />
        <axis xyz="0 0 1" />
        <limit lower="${radians(-86)}" upper="${radians(90)}" effort="7453.05" velocity="${radians(125)}"/>
    </joint>
    <joint name="${prefix}joint_4_r" type="revolute">
        <parent link="${prefix}link_3_u"/>
        <child link="${prefix}link_4_r"/>
        <origin xyz="0.300 -1.225 0" rpy="${radians(-90)} 0 0" />
        <axis xyz="0 0 1" />
        <limit lower="${radians(-360)}" upper="${radians(360)}" effort="1671.05" velocity="${radians(182)}"/>
    </joint>
    <joint name="${prefix}joint_5_b" type="revolute">
        <parent link="${prefix}link_4_r"/>
        <child link="${prefix}link_5_b"/>
        <origin xyz="0 0 0" rpy="${radians(90)} 0 0" />
        <axis xyz="0 0 1" />
        <limit lower="${radians(-130)}" upper="${radians(130)}" effort="1081.18" velocity="${radians(175)}"/>
    </joint>
    <joint name="${prefix}joint_6_t" type="revolute">
        <parent link="${prefix}link_5_b"/>
        <child link="${prefix}link_6_t"/>
        <origin xyz="0 -0.225 0" rpy="${radians(-90)} 0 0" />
        <axis xyz="0 0 1" />
        <limit lower="${radians(-360)}" upper="${radians(360)}" effort="926.73" velocity="${radians(265)}"/>
    </joint>
    <!-- end of joint list -->

    <!-- ROS base_link to Robot Manufacturer World Coordinates transform -->
    <link name="${prefix}base" />
    <joint name="${prefix}base_link-base" type="fixed">
        <origin xyz="0 0 0.650" rpy="0 0 0"/>
        <parent link="${prefix}base_link"/>
        <child link="${prefix}base"/>
    </joint>

    <!-- ROS-Industrial 'flange' frame: attachment point for EEF models -->
    <link name="${prefix}flange" />
    <joint name="${prefix}joint_6_t-flange" type="fixed">
        <origin xyz="0 0 0" rpy="0 ${radians(90)} 0" />
        <parent link="${prefix}link_6_t" />
        <child link="${prefix}flange" />
    </joint>

    <!-- ROS-Industrial 'tool0' frame: all-zeros tool frame -->
    <link name="${prefix}tool0" />
    <joint name="${prefix}flange-tool0" type="fixed">
        <origin xyz="0 0 0" rpy="${pi} ${-pi/2.0} 0" />
        <parent link="${prefix}flange" />
        <child link="${prefix}tool0" />
    </joint>
</xacro:macro>
</robot>
