<?xml version="1.0" ?>
<robot xmlns:xacro="http://ros.org/wiki/xacro">
  <xacro:macro name="motoman_mpx1950" params="prefix">
    <xacro:include filename="$(find motoman_resources)/urdf/common_materials.xacro"/>

    <!-- link list -->
    <link name="${prefix}base_link">
      <visual>
        <geometry>
          <mesh filename="package://motoman_mpx1950_support/meshes/mpx1950/visual/base_link.dae"/>
        </geometry>
        <xacro:material_yaskawa_blue/>
      </visual>
      <collision>
        <geometry>
          <mesh filename="package://motoman_mpx1950_support/meshes/mpx1950/collision/base_link.stl"/>
        </geometry>
      </collision>
    </link>
    <link name="${prefix}link_1_s">
      <visual>
        <geometry>
          <mesh filename="package://motoman_mpx1950_support/meshes/mpx1950/visual/link_1_s.dae"/>
        </geometry>
        <xacro:material_yaskawa_blue/>
      </visual>
      <collision>
        <geometry>
          <mesh filename="package://motoman_mpx1950_support/meshes/mpx1950/collision/link_1_s.stl"/>
        </geometry>
      </collision>
    </link>
    <link name="${prefix}link_2_l">
      <visual>
        <geometry>
          <mesh filename="package://motoman_mpx1950_support/meshes/mpx1950/visual/link_2_l.dae"/>
        </geometry>
        <xacro:material_yaskawa_blue/>
      </visual>
      <collision>
        <geometry>
          <mesh filename="package://motoman_mpx1950_support/meshes/mpx1950/collision/link_2_l.stl"/>
        </geometry>
      </collision>
    </link>
    <link name="${prefix}link_3_u">
      <visual>
        <geometry>
          <mesh filename="package://motoman_mpx1950_support/meshes/mpx1950/visual/link_3_u.dae"/>
        </geometry>
        <xacro:material_yaskawa_blue/>
      </visual>
      <collision>
        <geometry>
          <mesh filename="package://motoman_mpx1950_support/meshes/mpx1950/collision/link_3_u.stl"/>
        </geometry>
      </collision>
    </link>
    <link name="${prefix}link_4_r">
      <visual>
        <geometry>
          <mesh filename="package://motoman_mpx1950_support/meshes/mpx1950/visual/link_4_r.dae"/>
        </geometry>
        <xacro:material_yaskawa_blue/>
      </visual>
      <collision>
        <geometry>
          <mesh filename="package://motoman_mpx1950_support/meshes/mpx1950/collision/link_4_r.stl"/>
        </geometry>
      </collision>
    </link>
    <link name="${prefix}link_5_b">
      <visual>
        <geometry>
          <mesh filename="package://motoman_mpx1950_support/meshes/mpx1950/visual/link_5_b.dae"/>
        </geometry>
        <xacro:material_yaskawa_blue/>
      </visual>
      <collision>
        <geometry>
          <mesh filename="package://motoman_mpx1950_support/meshes/mpx1950/collision/link_5_b.stl"/>
        </geometry>
      </collision>
    </link>
    <link name="${prefix}link_6_t">
      <visual>
        <geometry>
          <mesh filename="package://motoman_mpx1950_support/meshes/mpx1950/visual/link_6_t.dae"/>
        </geometry>
        <xacro:material_yaskawa_silver/>
      </visual>
      <collision>
        <geometry>
          <mesh filename="package://motoman_mpx1950_support/meshes/mpx1950/collision/link_6_t.stl"/>
        </geometry>
      </collision>
    </link>
    <!-- end of link list -->

    <!-- joint list -->
    <joint name="${prefix}joint_1_s" type="revolute">
      <parent link="${prefix}base_link"/>
      <child link="${prefix}link_1_s"/>
      <origin xyz="0 0 0.500" rpy="0 0 0" />
      <axis xyz="0 0 1" />
      <limit lower="${radians(-170)}" upper="${radians(170)}" effort="2940" velocity="${radians(180.4)}"/>
    </joint>
    <joint name="${prefix}joint_2_l" type="revolute">
      <parent link="${prefix}link_1_s"/>
      <child link="${prefix}link_2_l"/>
      <origin xyz="0 0 0" rpy="0 0 0" />
      <axis xyz="0 1 0" />
      <limit lower="${radians(-100)}" upper="${radians(140)}" effort="2940" velocity="${radians(180.4)}"/>
    </joint>
    <joint name="${prefix}joint_3_u" type="revolute">
      <parent link="${prefix}link_2_l"/>
      <child link="${prefix}link_3_u"/>
      <origin xyz="0 0 0.725" rpy="0 0 0" />
      <axis xyz="0 -1 0" />
      <limit lower="${radians(-62)}" upper="${radians(235)}" effort="1470" velocity="${radians(180.2)}"/>
    </joint>
    <joint name="${prefix}joint_4_r" type="revolute">
      <parent link="${prefix}link_3_u"/>
      <child link="${prefix}link_4_r"/>
      <origin xyz="0.725 0 0.015" rpy="0 0 0" />
      <axis xyz="-1 0 0" />
      <limit lower="${radians(-200)}" upper="${radians(200)}" effort="215.6" velocity="${radians(360)}"/>
    </joint>
    <joint name="${prefix}joint_5_b" type="revolute">
      <parent link="${prefix}link_4_r"/>
      <child link="${prefix}link_5_b"/>
      <origin xyz="0 0 0" rpy="0 0 0" />
      <axis xyz="0 -1 0" />
      <limit lower="${radians(-150)}" upper="${radians(150)}" effort="96.04" velocity="${radians(400)}"/>
    </joint>
    <joint name="${prefix}joint_6_t" type="revolute">
      <parent link="${prefix}link_5_b"/>
      <child link="${prefix}link_6_t"/>
      <origin xyz="0 0 0" rpy="0 0 0" />
      <axis xyz="-1 0 0" />
      <limit lower="${radians(-400)}" upper="${radians(400)}" effort="22.54" velocity="${radians(500)}"/>
    </joint>
    <!-- end of joint list -->

    <!-- ROS-Industrial 'flange' frame: attachment point for EEF models -->
    <link name="${prefix}flange"/>
    <joint name="${prefix}joint_6_t-flange" type="fixed">
      <origin xyz="0.100 0 0" rpy="0 0 0"/>
      <parent link="${prefix}link_6_t"/>
      <child link="${prefix}flange"/>
    </joint>

    <!-- ROS-Industrial 'tool0' frame: all-zeros tool frame -->
    <link name="${prefix}tool0"/>
    <joint name="${prefix}flange-tool0" type="fixed">
      <origin xyz="0 0 0" rpy="${radians(180)} ${radians(-90)} 0"/>
      <parent link="${prefix}flange"/>
      <child link="${prefix}tool0"/>
    </joint>

    <!-- ROS base_link to Robot Manufacturer World Coordinates transform -->
    <link name="${prefix}base" />
    <joint name="${prefix}base_link-base" type="fixed">
      <origin xyz="0 0 0.500" rpy="0 0 0"/>
      <parent link="${prefix}base_link"/>
      <child link="${prefix}base"/>
    </joint>
  </xacro:macro>
</robot>
