<?xml version="1.0" ?>
<robot xmlns:xacro="http://ros.org/wiki/xacro">
	<xacro:macro name="motoman_arm" params="name prefix parent *origin reflect">
		<link name="${prefix}link_1_s">
			<visual>
				<origin rpy="0 0 0" xyz="0 0 0"/>
				<geometry>
					<mesh filename="package://motoman_sda5f_support/meshes/dae/arm_left_link_1_s.dae"/>
				</geometry>
				<material name="blue">
					<color rgba="0.8 0.8 0.8 1"/>
				</material>
			</visual>
			<collision>
				<origin rpy="0 0 0" xyz="0 0 0"/>
				<geometry>
					<mesh filename="package://motoman_sda5f_support/meshes/dae/arm_left_link_1_s.dae" />
				</geometry>
				<material name="yellow"/>
			</collision>
		</link>
		<link name="${prefix}link_2_l">
			<visual>
				<origin rpy="0 0 0" xyz="0 0 0"/>
				<geometry>
					<mesh filename="package://motoman_sda5f_support/meshes/dae/arm_left_link_2_l.dae"/>
				</geometry>
				<material name="silver"/>
			</visual>
			<collision>
				<origin rpy="0 0 0" xyz="0 0 0"/>
				<geometry>
					<mesh filename="package://motoman_sda5f_support/meshes/dae/arm_left_link_2_l.dae"/>
				</geometry>
				<material name="yellow"/>
			</collision>
		</link>
		<link name="${prefix}link_3_e">
			<visual>
				<origin rpy="0 0 0" xyz="0 0 0"/>
				<geometry>
					<mesh filename="package://motoman_sda5f_support/meshes/dae/arm_left_link_3_e.dae"/>
				</geometry>
				<material name="blue"/>
			</visual>
			<collision>
				<origin rpy="0 0 0" xyz="0 0 0"/>
				<geometry>
					<mesh filename="package://motoman_sda5f_support/meshes/dae/arm_left_link_3_e.dae"/>
				</geometry>
				<material name="yellow"/>
			</collision>
		</link>
		<link name="${prefix}link_4_u">
			<visual>
				<origin rpy="0 0 0" xyz="0 0 0"/>
				<geometry>
					<mesh filename="package://motoman_sda5f_support/meshes/dae/arm_left_link_4_u.dae"/>
				</geometry>
				<material name="silver"/>
			</visual>
			<collision>
				<origin rpy="0 0 0" xyz="0 0 0"/>
				<geometry>
					<mesh filename="package://motoman_sda5f_support/meshes/dae/arm_left_link_4_u.dae"/>
				</geometry>
				<material name="yellow"/>
			</collision>
		</link>
		<link name="${prefix}link_5_r">
			<visual>
				<origin rpy="0 0 0" xyz="0 0 0"/>
				<geometry>
					<mesh filename="package://motoman_sda5f_support/meshes/dae/arm_left_link_5_r.dae"/>
				</geometry>
				<material name="blue"/>
			</visual>
			<collision>
				<origin rpy="0 0 0" xyz="0 0 0"/>
				<geometry>
					<mesh filename="package://motoman_sda5f_support/meshes/dae/arm_left_link_5_r.dae"/>
				</geometry>
				<material name="yellow"/>
			</collision>
		</link>
		<link name="${prefix}link_6_b">
			<visual>
				<origin rpy="0 0 0" xyz="0 0 0"/>
				<geometry>
					<mesh filename="package://motoman_sda5f_support/meshes/dae/arm_left_link_6_b.dae"/>
				</geometry>
				<material name="silver"/>
			</visual>
			<collision>
				<origin rpy="0 0 0" xyz="0 0 0"/>
				<geometry>
					<mesh filename="package://motoman_sda5f_support/meshes/dae/arm_left_link_6_b.dae"/>
				</geometry>
				<material name="yellow"/>
			</collision>
		</link>
		<link name="${prefix}link_7_t">
			<visual>
				<geometry>
					<mesh filename="package://motoman_sda5f_support/meshes/dae/arm_left_link_7_t.dae" />
				</geometry>
				<material name="blue"/>
			</visual>
			<collision>
				<geometry>
					<mesh filename="package://motoman_sda5f_support/meshes/dae/arm_left_link_7_t.dae" />
				</geometry>
				<material name="yellow"/>
			</collision>
		</link>
	    <link name="${prefix}link_tool0" />
		
		<joint name="${prefix}joint_1_s" type="revolute">
			<parent link="torso_link_b1"/>
			<child link="${prefix}link_1_s"/>
			<origin xyz="0.150 ${reflect*0.101} 0.1704" rpy="${reflect*-1.57} ${reflect*-1.57+1.57} 0"/>
			<axis xyz="0 0 ${reflect}" />
			<limit lower="-1.57" upper="4.71" effort="0" velocity="3.48" />
		</joint>
		<joint name="${prefix}joint_2_l" type="revolute">
			<parent link="${prefix}link_1_s"/>
			<child link="${prefix}link_2_l"/>
			<origin xyz="0.0195 0.0 0.142" rpy="-1.57 0 -1.57"/>
			<axis xyz="0 0 1" />
			<limit lower="-1.90" upper="1.90" effort="0" velocity="3.48" />
		</joint>
		<joint name="${prefix}joint_3_e" type="revolute">
			<parent link="${prefix}link_2_l"/>
			<child link="${prefix}link_3_e"/>
			<origin xyz="0.0 -0.165 -0.0195 " rpy="-1.57 0 3.14"/>
			<axis xyz="0 0 ${reflect}" />
			<limit lower="-2.95" upper="2.95" effort="0" velocity="3.48" />
		</joint>
		<joint name="${prefix}joint_4_u" type="revolute">
			<parent link="${prefix}link_3_e"/>
			<child link="${prefix}link_4_u"/>
			<origin xyz="-0.085 0.017 0.105" rpy="-1.57 0 0"/>
			<axis xyz="0 0 1" />
			<limit lower="-1.57" upper="2.00" effort="0" velocity="3.48" />
		</joint>
		<joint name="${prefix}joint_5_r" type="revolute">
			<parent link="${prefix}link_4_u"/>
			<child link="${prefix}link_5_r"/>
			<origin xyz="-0.134 -0.060 -0.017" rpy="-1.57 0 -1.57"/>
			<axis xyz="0 0 ${reflect}" />
			<limit lower="-3.13" upper="3.13" effort="14.7" velocity="3.48" />
		</joint>
		<joint name="${prefix}joint_6_b" type="revolute">
			<parent link="${prefix}link_5_r"/>
			<child link="${prefix}link_6_b"/>
			<origin xyz="0 0.015 -0.136" rpy="0 1.57 -1.57"/>
			<axis xyz="0 0 1" />
			<limit lower="-1.90" upper="1.90" effort="14.7" velocity="4.00" />
		</joint>
		<joint name="${prefix}joint_7_t" type="revolute">
			<parent link="${prefix}link_6_b"/>
			<child link="${prefix}link_7_t"/>
			<origin xyz="0.148 0.0 0.015" rpy="-1.57 0 1.57"/>
			<axis xyz="0 0 ${reflect}" />
			<limit lower="-3.13" upper="3.13" effort="7.35" velocity="6.10" />
		</joint>
    <joint name="${prefix}joint_tool0" type="fixed" >
      <origin xyz="0 0 -0.05" rpy="0 3.14 0"/>
      <parent link="${prefix}link_7_t" />
      <child link="${prefix}link_tool0" />
    </joint>
		<!-- end of joint list -->
	</xacro:macro>
</robot>
