<robot name="sia20d" >
  <link name="base_link" >
    <visual>
      <origin xyz="0 0 0.050"/>
      <geometry>
        <cylinder length="0.100" radius="0.200"/>
      </geometry>
      <material name="RED">
        <color rgba="1.0 0 0 1.0"/>
      </material>
    </visual>
  </link>

  <link name="link1" >
    <visual>
      <origin xyz="0 0 0.155"/>
      <geometry>
        <cylinder length="0.310" radius="0.120"/>
      </geometry>
      <material name="GREEN">
        <color rgba="0 1.0 0 1.0"/>
      </material>
    </visual>
  </link>

  <link name="link2" >
    <visual>
      <origin xyz="0 0 0.1225"/>
      <geometry>
        <cylinder length="0.245" radius="0.120"/>
      </geometry>
      <material name="BLUE">
        <color rgba="0 0 1.0 1.0"/>
      </material>
    </visual>
  </link>

  <link name="link3" >
    <visual>
      <origin xyz="0 0 0.1225"/>
      <geometry>
        <cylinder length="0.245" radius="0.104"/>
      </geometry>
      <material name="RED">
        <color rgba="1.0 0 0 1.0"/>
      </material>
    </visual>
  </link>

  <link name="link4" >
    <visual>
      <origin xyz="0 0 0.110"/>
      <geometry>
        <cylinder length="0.220" radius="0.104"/>
      </geometry>
      <material name="GREEN">
        <color rgba="0 1.0 0 1.0"/>
      </material>
    </visual>
  </link>

  <link name="link5" >
    <visual>
      <origin xyz="0 0 0.100"/>
      <geometry>
        <cylinder length="0.200" radius="0.086"/>
      </geometry>
      <material name="BLUE">
        <color rgba="0 0 1.0 1.0"/>
      </material>
    </visual>
  </link>

  <link name="link6" >
    <visual>
      <origin xyz="0 0 0.090"/>
      <geometry>
        <cylinder length="0.180" radius="0.086"/>
      </geometry>
      <material name="RED">
        <color rgba="1.0 0 0 1.0"/>
      </material>
    </visual>
  </link>

  <link name="link7" >
    <visual>
      <origin xyz="0 0 0.090"/>
      <geometry>
        <sphere radius="0.076"/>
      </geometry>
      <material name="GREEN">
        <color rgba="0 1.0 0 1.0"/>
      </material>
    </visual>
  </link>

  <joint name="joint1" type="revolute">
    <parent link="base_link"/>
    <child link="link1"/>
    <axis xyz="0 0 1" />
    <origin xyz="0 0 0.100" rpy="0 0 0" />
    <limit lower="-1.57" upper="1.57" effort="100" velocity="6.98" />
  </joint>

  <joint name="joint2" type="revolute">
    <parent link="link1"/>
    <child link="link2"/>
    <axis xyz="1 0 0" />
    <origin xyz="0 0 0.310" rpy="0 0 0" />
    <limit lower="-1.57" upper="1.57" effort="100" velocity="6.98" />
  </joint>

  <joint name="joint3" type="revolute">
    <parent link="link2"/>
    <child link="link3"/>
    <axis xyz="0 0 1" />
    <origin xyz="0 0 0.245" rpy="0 0 0" />
    <limit lower="-1.57" upper="1.57" effort="100" velocity="6.98" />
  </joint>

  <joint name="joint4" type="revolute">
    <parent link="link3"/>
    <child link="link4"/>
    <axis xyz="1 0 0" />
    <origin xyz="0 0 0.245" rpy="0 0 0" />
    <limit lower="-1.57" upper="1.57" effort="100" velocity="6.98" />
  </joint>

  <joint name="joint5" type="revolute">
    <parent link="link4"/>
    <child link="link5"/>
    <axis xyz="0 0 1" />
    <origin xyz="0 0 0.220" rpy="0 0 0" />
    <limit lower="-1.57" upper="1.57" effort="100" velocity="6.98" />
  </joint>
  
  <joint name="joint6" type="revolute">
    <parent link="link5"/>
    <child link="link6"/>
    <axis xyz="1 0 0" />
    <origin xyz="0 0 0.200" rpy="0 0 0" />
    <limit lower="-1.57" upper="1.57" effort="100" velocity="6.98" />
  </joint>
  
  <joint name="joint7" type="revolute">
    <parent link="link6"/>
    <child link="link7"/>
    <axis xyz="0 0 1" />
    <origin xyz="0 0 0.180" rpy="0 0 0" />
    <limit lower="-1.57" upper="1.57" effort="100" velocity="6.98" />
  </joint>

</robot>
