<?xml version="1.0" ?>
<!-- =================================================================================== -->
<!-- |    This document was autogenerated by xacro from /home/jtaylor/motoman/motoman_config/cfg/sia20d.xacro | -->
<!-- |    EDITING THIS FILE BY HAND IS NOT RECOMMENDED                                 | -->
<!-- =================================================================================== -->
<robot name="sia20d" xmlns:xacro="http://ros.org/wiki/xacro">
  <link name="Base">
    <visual>
      <geometry>
        <mesh filename="package://motoman_config/meshes/sia20d/visual/MOTOMAN_BASE.dae"/>
      </geometry>
    </visual>
    <collision>
      <geometry>
        <mesh filename="package://motoman_config/meshes/sia20d/collision/MOTOMAN_BASE_COLLISION.dae"/>
      </geometry>
    </collision>
  </link>
  <joint name="joint_S" type="revolute">
    <parent link="Base"/>
    <child link="Link_S"/>
    <origin xyz="0 0 0.41"/>
    <axis xyz="0 0 1"/>
    <limit effort="1000" lower="-3.142" upper="3.142" velocity="2.269"/>
  </joint>
  <link name="Link_S">
    <visual>
      <geometry>
        <mesh filename="package://motoman_config/meshes/sia20d/visual/MOTOMAN_AXIS_S.dae.dae"/>
      </geometry>
    </visual>
    <collision>
      <geometry>
        <mesh filename="package://motoman_config/meshes/sia20d/collision/MOTOMAN_AXIS_S_COLLISION.dae"/>
      </geometry>
    </collision>
  </link>
  <joint name="joint_L" type="revolute">
    <parent link="Link_S"/>
    <child link="Link_L"/>
    <origin xyz="0 0 0"/>
    <axis xyz="0 1 0"/>
    <limit effort="1000" lower="-1.92" upper="1.92" velocity="2.269"/>
  </joint>
  <link name="Link_L">
    <visual>
      <geometry>
        <mesh filename="package://motoman_config/meshes/sia20d/visual/MOTOMAN_AXIS_L.dae"/>
      </geometry>
    </visual>
    <collision>
      <geometry>
        <mesh filename="package://motoman_config/meshes/sia20d/collision/MOTOMAN_AXIS_L_COLLISION.dae"/>
      </geometry>
    </collision>
  </link>
  <joint name="joint_E" type="revolute">
    <parent link="Link_L"/>
    <child link="Link_E"/>
    <origin xyz="0 0 0.49"/>
    <axis xyz="0 0 1"/>
    <limit effort="1000" lower="-2.967" upper="2.967" velocity="2.967"/>
  </joint>
  <link name="Link_E">
    <visual>
      <geometry>
        <mesh filename="package://motoman_config/meshes/sia20d/visual/MOTOMAN_AXIS_E.dae"/>
      </geometry>
    </visual>
    <collision>
      <geometry>
        <mesh filename="package://motoman_config/meshes/sia20d/collision/MOTOMAN_AXIS_E_COLLISION.dae"/>
      </geometry>
    </collision>
  </link>
  <joint name="joint_U" type="revolute">
    <parent link="Link_E"/>
    <child link="Link_U"/>
    <origin xyz="0 0 0"/>
    <axis xyz="0 -1 0"/>
    <limit effort="1000" lower="-2.269" upper="2.269" velocity="2.967"/>
  </joint>
  <link name="Link_U">
    <visual>
      <geometry>
        <mesh filename="package://motoman_config/meshes/sia20d/visual/MOTOMAN_AXIS_U.dae"/>
      </geometry>
    </visual>
    <collision>
      <geometry>
        <mesh filename="package://motoman_config/meshes/sia20d/collision/MOTOMAN_AXIS_U_COLLISION.dae"/>
      </geometry>
    </collision>
  </link>
  <joint name="joint_R" type="revolute">
    <parent link="Link_U"/>
    <child link="Link_R"/>
    <origin xyz="0 0 0.42"/>
    <axis xyz="0 0 -1"/>
    <limit effort="1000" lower="-3.142" upper="3.142" velocity="3.491"/>
  </joint>
  <link name="Link_R">
    <visual>
      <geometry>
        <mesh filename="package://motoman_config/meshes/sia20d/visual/MOTOMAN_AXIS_R.dae"/>
      </geometry>
    </visual>
    <collision>
      <geometry>
        <mesh filename="package://motoman_config/meshes/sia20d/collision/MOTOMAN_AXIS_R_COLLISION.dae"/>
      </geometry>
    </collision>
  </link>
  <joint name="joint_B" type="revolute">
    <parent link="Link_R"/>
    <child link="Link_B"/>
    <origin xyz="0 0 0"/>
    <axis xyz="0 -1 0"/>
    <limit effort="1000" lower="-1.92" upper="1.92" velocity="3.491"/>
  </joint>
  <link name="Link_B">
    <visual>
      <geometry>
        <mesh filename="package://motoman_config/meshes/sia20d/visual/MOTOMAN_AXIS_B.dae"/>
      </geometry>
    </visual>
    <collision>
      <geometry>
        <mesh filename="package://motoman_config/meshes/sia20d/collision/MOTOMAN_AXIS_B_COLLISION.dae"/>
      </geometry>
    </collision>
  </link>
  <joint name="joint_T" type="revolute">
    <parent link="Link_B"/>
    <child link="tool0"/>
    <origin xyz="0 0 0"/>
    <axis xyz="0 0 -1"/>
    <limit effort="1000" lower="-3.142" upper="3.142" velocity="6.981"/>
  </joint>
  <link name="tool0">
    <visual>
      <geometry>
        <mesh filename="package://motoman_config/meshes/sia20d/visual/MOTOMAN_AXIS_T.dae"/>
      </geometry>
    </visual>
    <collision>
      <geometry>
        <mesh filename="package://motoman_config/meshes/sia20d/collision/MOTOMAN_AXIS_T_COLLISION.dae"/>
      </geometry>
    </collision>
  </link>
</robot>

