<?xml version="1.0"?>
<robot xmlns:xacro="http://ros.org/wiki/xacro">
<xacro:macro name="sia20d" params="prefix">
  <link name="${prefix}Base">
    <visual>
      <geometry>
        <mesh filename="package://motoman_config/meshes/sia20d/visual/MOTOMAN_BASE.dae"/>
      </geometry>
    </visual>
    <collision>
      <geometry>
        <mesh filename="package://motoman_config/meshes/sia20d/collision/MOTOMAN_BASE_COLLISION.dae" />
      </geometry>
    </collision>
  </link>

  <joint name="${prefix}joint_S" type="revolute">
    <parent link="${prefix}Base"/>
    <child link="${prefix}Link_S"/>
    <origin xyz="0 0 0.41" />
    <axis xyz="0 0 1" />
    <limit effort="1000" lower="-3.142" upper="3.142" velocity="2.269"/>
  </joint>

  <link name="${prefix}Link_S">
    <visual>
      <geometry>
        <mesh filename="package://motoman_config/meshes/sia20d/visual/MOTOMAN_AXIS_S.dae.dae" />
      </geometry>
    </visual>
    <collision>
      <geometry>
        <mesh filename="package://motoman_config/meshes/sia20d/collision/MOTOMAN_AXIS_S_COLLISION.dae" />
      </geometry>
    </collision>
  </link>

  <joint name="${prefix}joint_L" type="revolute">
    <parent link="${prefix}Link_S"/>
    <child link="${prefix}Link_L"/>
    <origin xyz="0 0 0" />
    <axis xyz="0 1 0" />
    <limit effort="1000" lower="-1.92" upper="1.92" velocity="2.269"/>
  </joint>

  <link name="${prefix}Link_L">
    <visual>
      <geometry>
        <mesh filename="package://motoman_config/meshes/sia20d/visual/MOTOMAN_AXIS_L.dae" />
      </geometry>
    </visual>
    <collision>
      <geometry>
        <mesh filename="package://motoman_config/meshes/sia20d/collision/MOTOMAN_AXIS_L_COLLISION.dae" />
      </geometry>
    </collision>
  </link>

  <joint name="${prefix}joint_E" type="revolute">
    <parent link="${prefix}Link_L"/>
    <child link="${prefix}Link_E"/>
    <origin xyz="0 0 0.49" />
    <axis xyz="0 0 1" />
    <limit effort="1000" lower="-2.967" upper="2.967" velocity="2.967"/>
  </joint>

  <link name="${prefix}Link_E">
    <visual>
      <geometry>
        <mesh filename="package://motoman_config/meshes/sia20d/visual/MOTOMAN_AXIS_E.dae" />
      </geometry>
    </visual>
    <collision>
      <geometry>
        <mesh filename="package://motoman_config/meshes/sia20d/collision/MOTOMAN_AXIS_E_COLLISION.dae" />
      </geometry>
    </collision>
  </link>

  <joint name="${prefix}joint_U" type="revolute">
    <parent link="${prefix}Link_E"/>
    <child link="${prefix}Link_U"/>
    <origin xyz="0 0 0" />
    <axis xyz="0 -1 0" />
    <limit effort="1000" lower="-2.269" upper="2.269" velocity="2.967"/>
  </joint>

  <link name="${prefix}Link_U">
    <visual>
      <geometry>
        <mesh filename="package://motoman_config/meshes/sia20d/visual/MOTOMAN_AXIS_U.dae" />
      </geometry>
    </visual>
    <collision>
      <geometry>
        <mesh filename="package://motoman_config/meshes/sia20d/collision/MOTOMAN_AXIS_U_COLLISION.dae" />
      </geometry>
    </collision>
  </link>

  <joint name="${prefix}joint_R" type="revolute">
    <parent link="${prefix}Link_U"/>
    <child link="${prefix}Link_R"/>
    <origin xyz="0 0 0.42" />
    <axis xyz="0 0 -1" />
    <limit effort="1000" lower="-3.142" upper="3.142" velocity="3.491"/>
  </joint>

  <link name="${prefix}Link_R">
    <visual>
      <geometry>
        <mesh filename="package://motoman_config/meshes/sia20d/visual/MOTOMAN_AXIS_R.dae" />
      </geometry>
    </visual>
    <collision>
      <geometry>
        <mesh filename="package://motoman_config/meshes/sia20d/collision/MOTOMAN_AXIS_R_COLLISION.dae" />
      </geometry>
    </collision>
  </link>

  <joint name="${prefix}joint_B" type="revolute">
    <parent link="${prefix}Link_R"/>
    <child link="${prefix}Link_B"/>
    <origin xyz="0 0 0" />
    <axis xyz="0 -1 0" />
    <limit effort="1000" lower="-1.92" upper="1.92" velocity="3.491"/>
  </joint>

  <link name="${prefix}Link_B">
    <visual>
      <geometry>
        <mesh filename="package://motoman_config/meshes/sia20d/visual/MOTOMAN_AXIS_B.dae" />
      </geometry>
    </visual>
    <collision>
      <geometry>
        <mesh filename="package://motoman_config/meshes/sia20d/collision/MOTOMAN_AXIS_B_COLLISION.dae" />
      </geometry>
    </collision>
  </link>

  <joint name="${prefix}joint_T" type="revolute">
    <parent link="${prefix}Link_B"/>
    <child link="${prefix}tool0"/>
    <origin xyz="0 0 0" />
    <axis xyz="0 0 -1" />
    <limit effort="1000" lower="-3.142" upper="3.142" velocity="6.981"/>
  </joint>

  <link name="${prefix}tool0">
    <visual>
      <geometry>
        <mesh filename="package://motoman_config/meshes/sia20d/visual/MOTOMAN_AXIS_T.dae" />
      </geometry>
    </visual>
    <collision>
      <geometry>
        <mesh filename="package://motoman_config/meshes/sia20d/collision/MOTOMAN_AXIS_T_COLLISION.dae" />
      </geometry>
    </collision>
  </link>
</xacro:macro>
</robot>
