<?xml version="1.0" ?>
<robot xmlns:xacro="http://ros.org/wiki/xacro">
  <xacro:macro name="motoman_mh5l" params="prefix">
    <xacro:include filename="$(find motoman_resources)/urdf/common_materials.xacro"/>

    <!-- link list -->
    <link name="${prefix}base_link">
      <visual>
        <origin xyz="0 0 0" rpy="0 0 0" />
        <geometry>
          <mesh filename="package://motoman_mh5_support/meshes/mh5/visual/base_link.stl" />
        </geometry>
        <xacro:material_yaskawa_white/>
      </visual>
      <collision>
        <origin xyz="0 0 0" rpy="0 0 0" />
        <geometry>
          <mesh filename="package://motoman_mh5_support/meshes/mh5/collision/base_link.stl" />
        </geometry>
      </collision>
    </link>
    <link name="${prefix}link_1_s">
      <visual>
        <origin xyz="0 0 0" rpy="0 0 0" />
        <geometry>
          <mesh filename="package://motoman_mh5_support/meshes/mh5/visual/link_1_s.stl"/>
        </geometry>
        <xacro:material_yaskawa_white/>
      </visual>
      <collision>
        <origin xyz="0 0 0" rpy="0 0 0" />
        <geometry>
          <mesh filename="package://motoman_mh5_support/meshes/mh5/collision/link_1_s.stl" />
        </geometry>
      </collision>
    </link>
    <link name="${prefix}link_2_l">
      <visual>
        <origin xyz="0 0 0" rpy="0 0 0" />
        <geometry>
          <mesh filename="package://motoman_mh5_support/meshes/mh5l/visual/link_2_l.stl"/>
        </geometry>
        <xacro:material_yaskawa_white/>
      </visual>
      <collision>
        <origin xyz="0 0 0" rpy="0 0 0" />
        <geometry>
          <mesh filename="package://motoman_mh5_support/meshes/mh5l/collision/link_2_l.stl" />
        </geometry>
      </collision>
    </link>
    <link name="${prefix}link_3_u">
      <visual>
        <origin xyz="0 0 0" rpy="0 0 0" />
        <geometry>
          <mesh filename="package://motoman_mh5_support/meshes/mh5/visual/link_3_u.stl"/>
        </geometry>
        <xacro:material_yaskawa_white/>
      </visual>
      <collision>
        <origin xyz="0 0 0" rpy="0 0 0" />
        <geometry>
          <mesh filename="package://motoman_mh5_support/meshes/mh5/collision/link_3_u.stl" />
        </geometry>
      </collision>
    </link>
    <link name="${prefix}link_4_r">
      <visual>
        <origin xyz="0 0 0" rpy="0 0 0" />
        <geometry>
          <mesh filename="package://motoman_mh5_support/meshes/mh5l/visual/link_4_r.stl"/>
        </geometry>
        <xacro:material_yaskawa_white/>
      </visual>
      <collision>
        <origin xyz="0 0 0" rpy="0 0 0" />
        <geometry>
          <mesh filename="package://motoman_mh5_support/meshes/mh5l/collision/link_4_r.stl" />
        </geometry>
      </collision>
    </link>
    <link name="${prefix}link_5_b">
      <visual>
        <origin xyz="0 0 0" rpy="0 0 0" />
        <geometry>
          <mesh filename="package://motoman_mh5_support/meshes/mh5/visual/link_5_b.stl"/>
        </geometry>
        <xacro:material_yaskawa_white/>
      </visual>
      <collision>
        <origin xyz="0 0 0" rpy="0 0 0" />
        <geometry>
          <mesh filename="package://motoman_mh5_support/meshes/mh5/collision/link_5_b.stl" />
        </geometry>
      </collision>
    </link>
    <link name="${prefix}link_6_t">
      <visual>
        <origin xyz="0 0 0" rpy="0 0 0" />
        <geometry>
          <mesh filename="package://motoman_mh5_support/meshes/mh5/visual/link_6_t.stl" />
        </geometry>
        <xacro:material_yaskawa_white/>
      </visual>
      <collision>
        <origin xyz="0 0 0" rpy="0 0 0" />
        <geometry>
          <mesh filename="package://motoman_mh5_support/meshes/mh5/collision/link_6_t.stl" />
        </geometry>
      </collision>
    </link>
    <!-- end of link list -->

    <!-- joint list -->
    <joint name="${prefix}joint_1_s" type="revolute">
      <parent link="${prefix}base_link"/>
      <child link="${prefix}link_1_s"/>
      <origin xyz="0 0 0.330" rpy="0 0 0"/>
      <axis xyz="0 0 1" />
      <limit lower="-${radians(170)}" upper="${radians(170)}" effort="303.8" velocity="${radians(270)}" />
    </joint>
    <joint name="${prefix}joint_2_l" type="revolute">
      <parent link="${prefix}link_1_s"/>
      <child link="${prefix}link_2_l"/>
      <origin xyz="0.0880 0 0.00" rpy="0 0 0"/>
      <axis xyz="0 1 0" />
      <limit lower="-${radians(65)}" upper="${radians(150)}" effort="205.8" velocity="${radians(280)}" />
    </joint>
    <joint name="${prefix}joint_3_u" type="revolute">
      <parent link="${prefix}link_2_l"/>
      <child link="${prefix}link_3_u"/>
      <origin xyz="0 0 0.400" rpy="0 0 0"/>
      <axis xyz="0 -1 0" />
      <limit lower="-${radians(70)}" upper="${radians(190)}" effort="85.5" velocity="${radians(300)}" />
    </joint>
    <joint name="${prefix}joint_4_r" type="revolute">
      <parent link="${prefix}link_3_u"/>
      <child link="${prefix}link_4_r"/>
      <origin xyz="0 0 0.040" rpy="0 0 0"/>
      <axis xyz="-1 0 0" />
      <limit lower="-${radians(190)}" upper="${radians(190)}" effort="44.7" velocity="${radians(450)}" />
    </joint>
    <joint name="${prefix}joint_5_b" type="revolute">
      <parent link="${prefix}link_4_r"/>
      <child link="${prefix}link_5_b"/>
      <origin xyz="0.405 0 0" rpy="0 0 0"/>
      <axis xyz="0 -1 0" />
      <limit lower="-${radians(135)}" upper="${radians(135)}" effort="18.0" velocity="${radians(450)}" />
    </joint>
    <joint name="${prefix}joint_6_t" type="revolute">
      <parent link="${prefix}link_5_b"/>
      <child link="${prefix}link_6_t"/>
      <origin xyz="0.080 0 0" rpy="0 0 0"/>
      <axis xyz="-1 0 0" />
      <limit lower="-${radians(360)}" upper="${radians(360)}" effort="18.0" velocity="${radians(720)}" />
    </joint>
    <!-- end of joint list -->

    <!-- ROS base_link to Robot Manufacturer (Motoman) World Coordinates transform -->
    <link name="${prefix}base" />
    <joint name="${prefix}base_link-base" type="fixed">
        <parent link="${prefix}base_link"/>
        <child link="${prefix}base"/>
        <origin xyz="0 0 0.330" rpy="0 0 0"/>
    </joint>

    <!-- ROS-Industrial 'flange' frame: attachment point for EEF models -->
    <link name="${prefix}flange" />
    <joint name="${prefix}joint_6_t-flange" type="fixed">
      <parent link="${prefix}link_6_t" />
      <child link="${prefix}flange" />
      <origin xyz="0 0 0" rpy="0 0 0" />
    </joint>

    <!-- ROS-Industrial 'tool0' frame: all-zeros tool frame -->
    <link name="${prefix}tool0"/>
    <joint name="${prefix}joint_6_t-tool0" type="fixed">
        <parent link="${prefix}link_6_t"/>
        <child link="${prefix}tool0"/>
        <origin xyz="0 0 0" rpy="${radians(180)} ${radians(-90)} 0"/>
    </joint>

  </xacro:macro>
</robot>
