<?xml version="1.0" ?>
<robot xmlns:xacro="http://ros.org/wiki/xacro">
<xacro:macro name="motoman_gp180_120" params="prefix">

    <!-- Properties -->
    <material name="yaskawa_blue">
          <color rgba="0.12941 0.14902 0.74902 1" />
    </material>

    <property name="DEG2RAD" value="0.017453292519943295" />

    <!-- link list -->
    <link name="${prefix}base_link">
        <visual>
            <origin rpy="${DEG2RAD * 90} 0 0" />
            <geometry>
                <mesh filename="package://motoman_gp180_120_support/meshes/visual/BASE_AXIS.stl" scale="0.001 0.001 0.001"/>
            </geometry>
            <material name="yaskawa_blue"/>
        </visual>
        <collision>
            <origin rpy="${DEG2RAD * 90} 0 0" />
            <geometry>
                <mesh filename="package://motoman_gp180_120_support/meshes/collision/BASE_AXIS.stl" scale="0.001 0.001 0.001"/>
            </geometry>
        </collision>
    </link>
    <link name="${prefix}link_1_s">
        <visual>
            <origin xyz="0 0 -0.317" rpy="${DEG2RAD * 90} 0 0" />
            <geometry>
                <mesh filename="package://motoman_gp180_120_support/meshes/visual/S_AXIS.stl" scale="0.001 0.001 0.001"/>
            </geometry>
            <material name="yaskawa_blue"/>
        </visual>
        <collision>
            <origin xyz="0 0 -0.317" rpy="${DEG2RAD * 90} 0 0" />
            <geometry>
                <mesh filename="package://motoman_gp180_120_support/meshes/collision/S_AXIS.stl" scale="0.001 0.001 0.001"/>
            </geometry>
        </collision>
    </link>
    <link name="${prefix}link_2_l">
        <visual>
            <origin xyz="0.325 0.07 -0.650" rpy="${DEG2RAD * 90} 0 0" />
            <geometry>
                <mesh filename="package://motoman_gp180_120_support/meshes/visual/L_AXIS.stl" scale="0.001 0.001 0.001"/>
            </geometry>
            <material name="yaskawa_blue"/>
        </visual>
        <collision>
            <origin xyz="0.325 0.07 -0.650" rpy="${DEG2RAD * 90} 0 0" />
            <geometry>
                <mesh filename="package://motoman_gp180_120_support/meshes/collision/L_AXIS.stl" scale="0.001 0.001 0.001"/>
            </geometry>
        </collision>
    </link>
    <link name="${prefix}link_3_u">
        <visual>
            <origin xyz="0.325 0.0415 -1.800" rpy="${DEG2RAD * 90} 0 0" />
            <geometry>
                <mesh filename="package://motoman_gp180_120_support/meshes/visual/U_AXIS.stl" scale="0.001 0.001 0.001"/>
            </geometry>
            <material name="yaskawa_blue"/>
        </visual>
        <collision>
            <origin xyz="0.325 0.0415 -1.800" rpy="${DEG2RAD * 90} 0 0" />
            <geometry>
                <mesh filename="package://motoman_gp180_120_support/meshes/collision/U_AXIS.stl" scale="0.001 0.001 0.001"/>
            </geometry>
        </collision>
    </link>
    <link name="${prefix}link_4_r">
        <visual>
            <origin xyz="1.723 0 -2.100" rpy="${DEG2RAD * 90} 0 0" />
            <geometry>
                <mesh filename="package://motoman_gp180_120_support/meshes/visual/R_AXIS.stl" scale="0.001 0.001 0.001"/>
            </geometry>
            <material name="yaskawa_blue"/>
        </visual>
        <collision>
            <origin xyz="1.723 0 -2.100" rpy="${DEG2RAD * 90} 0 0" />
            <geometry>
                <mesh filename="package://motoman_gp180_120_support/meshes/collision/R_AXIS.stl" scale="0.001 0.001 0.001"/>
            </geometry>
        </collision>
    </link>
    <link name="${prefix}link_5_b">
        <visual>
            <origin xyz="1.915 -0.082 -2.100" rpy="${DEG2RAD * 90} 0 0" />
            <geometry>
                <mesh filename="package://motoman_gp180_120_support/meshes/visual/B_AXIS.stl" scale="0.001 0.001 0.001"/>
            </geometry>
            <material name="yaskawa_blue"/>
        </visual>
        <collision>
            <origin xyz="1.915 -0.082 -2.100" rpy="${DEG2RAD * 90} 0 0" />
            <geometry>
                <mesh filename="package://motoman_gp180_120_support/meshes/collision/B_AXIS.stl" scale="0.001 0.001 0.001"/>
            </geometry>
        </collision>
    </link>
    <link name="${prefix}link_6_t">
        <visual>
            <origin xyz="2.1145 0 -2.100" rpy="${DEG2RAD * 90} 0 0" />
            <geometry>
                <mesh filename="package://motoman_gp180_120_support/meshes/visual/T_AXIS.stl" scale="0.001 0.001 0.001"/>
            </geometry>
            <material name="yaskawa_blue"/>
        </visual>
        <collision>
            <origin xyz="2.1145 0 -2.100" rpy="${DEG2RAD * 90} 0 0" />
            <geometry>
                <mesh filename="package://motoman_gp180_120_support/meshes/collision/T_AXIS.stl" scale="0.001 0.001 0.001"/>
            </geometry>
        </collision>
    </link>
    <link name="${prefix}tool0"/>
    <!-- end of link list -->

    <!-- joint list -->
    <joint name="${prefix}joint_1_s" type="revolute">
        <parent link="${prefix}base_link"/>
        <child link="${prefix}link_1_s"/>
        <origin xyz="0 0 0.317" rpy="0 0 0" />
        <axis xyz="0 0 1" />
        <limit lower="${-DEG2RAD * 180}" upper="${DEG2RAD * 180}" effort="1300" velocity="${DEG2RAD * 125}"/>
    </joint>
    <joint name="${prefix}joint_2_l" type="revolute">
        <parent link="${prefix}link_1_s"/>
        <child link="${prefix}link_2_l"/>
        <origin xyz="-0.325 -0.07 0.333" rpy="0 0 0" />
        <axis xyz="0 -1 0" />
        <limit lower="${-DEG2RAD * 60}" upper="${DEG2RAD * 76}" effort="1100" velocity="${DEG2RAD * 115}"/>
    </joint>
    <joint name="${prefix}joint_3_u" type="revolute">
        <parent link="${prefix}link_2_l"/>
        <child link="${prefix}link_3_u"/>
        <origin xyz="0 0.0285 1.150" rpy="0 0 0" />
        <axis xyz="0 -1 0" />
        <limit lower="${-DEG2RAD * 86}" upper="${DEG2RAD * 90}" effort="900" velocity="${DEG2RAD * 125}"/>
    </joint>
    <joint name="${prefix}joint_4_r" type="revolute">
        <parent link="${prefix}link_3_u"/>
        <child link="${prefix}link_4_r"/>
        <origin xyz="-1.398 0.0415 0.300" rpy="0 0 0" />
        <axis xyz="-1 0 0" />
        <limit lower="${-DEG2RAD * 360}" upper="${DEG2RAD * 360}" effort="883" velocity="${DEG2RAD * 182}"/>
    </joint>
    <joint name="${prefix}joint_5_b" type="revolute">
        <parent link="${prefix}link_4_r"/>
        <child link="${prefix}link_5_b"/>
        <origin xyz="-0.192 0.082 0" rpy="0 0 0" />
        <axis xyz="0 -1 0" />
        <limit lower="${-DEG2RAD * 130}" upper="${DEG2RAD * 130}" effort="883" velocity="${DEG2RAD * 175}"/>
    </joint>
    <joint name="${prefix}joint_6_t" type="revolute">
        <parent link="${prefix}link_5_b"/>
        <child link="${prefix}link_6_t"/>
        <origin xyz="-0.1995 -0.082 0" rpy="0 0 0" />
        <axis xyz="-1 0 0" />
        <limit lower="${-DEG2RAD * 360}" upper="${DEG2RAD * 360}" effort="520" velocity="${DEG2RAD * 265}"/>
    </joint>
    <joint name="${prefix}joint_6_t-tool0" type="fixed">
        <origin xyz="-0.0255 0 0" rpy="${DEG2RAD * 180} ${-DEG2RAD * 180} 0"/>
        <parent link="${prefix}link_6_t"/>
        <child link="${prefix}tool0"/>
    </joint>
    <!-- end of joint list -->

    <!-- ROS base_link to Robot Manufacturer World Coordinates transform -->
    <link name="${prefix}base" />
    <joint name="${prefix}base_link-base" type="fixed">
        <origin xyz="0 0 0.317" rpy="0 0 0"/>
        <parent link="${prefix}base_link"/>
        <child link="${prefix}base"/>
    </joint>

</xacro:macro>
</robot>
